Workbook

Sheet Bank
A1: student_id | B1: course_level | C1: performance_score | D1: aptitude_score | N1: Advanced | O1: Intermediate | P1: Foundation | R1: Advanced | S1: Intermediate | T1: Foundation | V1: course_level | W1: performance_score | X1: aptitude_score
A2: 1 | B2: Advanced | C2: 370 | D2: 72 | N2: 370 | O2: 255 | P2: 180 | R2: 72 | S2: 74 | T2: 20 | V2: Advanced | W2: 370 | X2: 72
A3: 2 | B3: Advanced | C3: 365 | D3: 90 | N3: 365 | O3: 235 | P3: 190 | R3: 90 | S3: 36 | T3: 13 | V3: Advanced | W3: 365 | X3: 90
A4: 3 | B4: Advanced | C4: 355 | D4: 68 | N4: 355 | O4: 265 | P4: 200 | R4: 68 | S4: 50 | T4: 12 | V4: Advanced | W4: 355 | X4: 68
A5: 4 | B5: Advanced | C5: 345 | D5: 84 | N5: 345 | O5: 350 | P5: 245 | R5: 84 | S5: 67 | T5: 21 | V5: Advanced | W5: 345 | X5: 84
A6: 5 | B6: Advanced | C6: 355 | D6: 72 | N6: 355 | O6: 260 | P6: 180 | R6: 72 | S6: 65 | T6: 25 | V6: Advanced | W6: 355 | X6: 72
A7: 6 | B7: Advanced | C7: 355 | D7: 83 | N7: 355 | O7: 250 | P7: 175 | R7: 83 | S7: 65 | T7: 17 | V7: Advanced | W7: 355 | X7: 83
A8: 7 | B8: Advanced | C8: 375 | D8: 83 | N8: 375 | O8: 280 | P8: 205 | R8: 83 | S8: 49 | T8: 14 | V8: Advanced | W8: 375 | X8: 83
A9: 8 | B9: Advanced | C9: 360 | D9: 81 | N9: 360 | O9: 265 | P9: 185 | R9: 81 | S9: 46 | T9: 21 | V9: Advanced | W9: 360 | X9: 81
A10: 9 | B10: Advanced | C10: 345 | D10: 79 | N10: 345 | O10: 265 | P10: 215 | R10: 79 | S10: 52 | T10: 40 | V10: Advanced | W10: 345 | X10: 79
A11: 10 | B11: Advanced | C11: 355 | D11: 89 | H11: performance_score | K11: aptitude_score | N11: 355 | O11: 280 | P11: 170 | R11: 89 | S11: 51 | T11: 21 | V11: Advanced | W11: 355 | X11: 89
A12: 11 | B12: Advanced | C12: 340 | D12: 94 | N12: 340 | O12: 205 | P12: 180 | R12: 94 | S12: 31 | T12: 26 | V12: Advanced | W12: 340 | X12: 94
A13: 12 | B13: Advanced | C13: 310 | D13: 52 | H13: Mean | I13: 254.06667 | K13: Mean | L13: 44.24 | N13: 310 | O13: 290 | P13: 175 | R13: 52 | S13: 38 | T13: 16 | V13: Advanced | W13: 310 | X13: 52
A14: 13 | B14: Advanced | C14: 375 | D14: 81 | H14: Standard Error | I14: 5.3303375 | K14: Standard Error | L14: 1.9782188 | N14: 375 | O14: 280 | P14: 165 | R14: 81 | S14: 57 | T14: 22 | V14: Advanced | W14: 375 | X14: 81
A15: 14 | B15: Advanced | C15: 360 | D15: 68 | H15: Median | I15: 247.5 | K15: Median | L15: 38 | N15: 360 | O15: 275 | P15: 205 | R15: 68 | S15: 52 | T15: 28 | V15: Advanced | W15: 360 | X15: 68
A16: 15 | B16: Advanced | C16: 380 | D16: 88 | H16: Mode | I16: 355 | K16: Mode | L16: 21 | N16: 380 | O16: 280 | P16: 170 | R16: 88 | S16: 59 | T16: 19 | V16: Advanced | W16: 380 | X16: 88
A17: 16 | B17: Advanced | C17: 355 | D17: 87 | H17: Standard Deviation | I17: 65.283035 | K17: Standard Deviation | L17: 24.228133 | N17: 355 | O17: 205 | P17: 195 | R17: 87 | S17: 32 | T17: 27 | V17: Advanced | W17: 355 | X17: 87
A18: 17 | B18: Advanced | C18: 355 | D18: 86 | H18: Sample Variance | I18: 4261.8747 | K18: Sample Variance | L18: 587.00242 | N18: 355 | O18: 290 | P18: 195 | R18: 86 | S18: 38 | T18: 35 | V18: Advanced | W18: 355 | X18: 86
A19: 18 | B19: Advanced | C19: 310 | D19: 66 | H19: Kurtosis | I19: -1.1419921 | K19: Kurtosis | L19: -0.87170446 | N19: 310 | O19: 315 | P19: 190 | R19: 66 | S19: 69 | T19: 20 | V19: Advanced | W19: 310 | X19: 66
A20: 19 | B20: Advanced | C20: 355 | D20: 91 | H20: Skewness | I20: 0.35309978 | K20: Skewness | L20: 0.58310354 | N20: 355 | O20: 310 | P20: 200 | R20: 91 | S20: 54 | T20: 21 | V20: Advanced | W20: 355 | X20: 91
A21: 20 | B21: Advanced | C21: 360 | D21: 94 | H21: Range | I21: 225 | K21: Range | L21: 88 | N21: 360 | O21: 330 | P21: 190 | R21: 94 | S21: 88 | T21: 19 | V21: Advanced | W21: 360 | X21: 94
A22: 21 | B22: Advanced | C22: 355 | D22: 71 | H22: Minimum | I22: 155 | K22: Minimum | L22: 9 | N22: 355 | O22: 230 | P22: 160 | R22: 71 | S22: 40 | T22: 16 | V22: Advanced | W22: 355 | X22: 71
A23: 22 | B23: Advanced | C23: 360 | D23: 97 | H23: Maximum | I23: 380 | K23: Maximum | L23: 97 | N23: 360 | O23: 265 | P23: 190 | R23: 97 | S23: 65 | T23: 14 | V23: Advanced | W23: 360 | X23: 97
A24: 23 | B24: Advanced | C24: 345 | D24: 56 | H24: Sum | I24: 38110 | K24: Sum | L24: 6636 | N24: 345 | O24: 355 | P24: 175 | R24: 56 | S24: 90 | T24: 19 | V24: Advanced | W24: 345 | X24: 56
... A28: 27 | B28: Advanced | C28: 315 | D28: 55 | H28: Confidence Level(95,0%) | I28: 10.532817 | K28: Confidence Level(95,0%) | L28: 3.9089863 | N28: 315 | O28: 190 | P28: 210 | R28: 55 | S28: 42 | T28: 33 | V28: Advanced | W28: 315 | X28: 55
A29: 28 | B29: Advanced | C29: 305 | D29: 36 | N29: 305 | O29: 220 | P29: 190 | R29: 36 | S29: 33 | T29: 25 | V29: Advanced | W29: 305 | X29: 36
A30: 29 | B30: Advanced | C30: 305 | D30: 45 | N30: 305 | O30: 230 | P30: 175 | R30: 45 | S30: 21 | T30: 25 | V30: Advanced | W30: 305 | X30: 45
A31: 30 | B31: Advanced | C31: 280 | D31: 33 | N31: 280 | O31: 235 | P31: 190 | R31: 33 | S31: 18 | T31: 21 | V31: Advanced | W31: 280 | X31: 33
A32: 31 | B32: Advanced | C32: 335 | D32: 81 | N32: 335 | O32: 260 | P32: 170 | R32: 81 | S32: 23 | T32: 25 | V32: Advanced | W32: 335 | X32: 81
A33: 32 | B33: Advanced | C33: 295 | D33: 64 | N33: 295 | O33: 215 | P33: 175 | R33: 64 | S33: 25 | T33: 21 | V33: Advanced | W33: 295 | X33: 64
A34: 33 | B34: Advanced | C34: 300 | D34: 65 | N34: 300 | O34: 215 | P34: 170 | R34: 65 | S34: 19 | T34: 21 | V34: Advanced | W34: 300 | X34: 65
A35: 34 | B35: Advanced | C35: 305 | D35: 45 | N35: 305 | O35: 205 | P35: 175 | R35: 45 | S35: 44 | T35: 33 | V35: Advanced | W35: 305 | X35: 45
A36: 35 | B36: Advanced | C36: 285 | D36: 61 | N36: 285 | O36: 215 | P36: 180 | R36: 61 | S36: 42 | T36: 22 | V36: Advanced | W36: 285 | X36: 61
A37: 36 | B37: Advanced | C37: 265 | D37: 75 | N37: 265 | O37: 235 | P37: 220 | R37: 75 | S37: 33 | T37: 29 | V37: Advanced | W37: 265 | X37: 75
A38: 37 | B38: Advanced | C38: 320 | D38: 50 | N38: 320 | O38: 245 | P38: 160 | R38: 50 | S38: 22 | T38: 17 | V38: Advanced | W38: 320 | X38: 50
A39: 38 | B39: Advanced | C39: 300 | D39: 72 | N39: 300 | O39: 225 | P39: 175 | R39: 72 | S39: 24 | T39: 17 | V39: Advanced | W39: 300 | X39: 72
A40: 39 | B40: Advanced | C40: 360 | D40: 92 | N40: 360 | O40: 240 | P40: 185 | R40: 92 | S40: 45 | T40: 29 | V40: Advanced | W40: 360 | X40: 92
... A42: 41 | B42: Advanced | C42: 250 | D42: 36 | N42: 250 | O42: 295 | P42: 195 | R42: 36 | S42: 41 | T42: 30 | V42: Advanced | W42: 250 | X42: 36
A43: 42 | B43: Advanced | C43: 265 | D43: 50 | H43: Interpretation | N43: 265 | O43: 190 | P43: 180 | R43: 50 | S43: 14 | T43: 18 | V43: Advanced | W43: 265 | X43: 50
A44: 43 | B44: Advanced | C44: 275 | D44: 37 | N44: 275 | O44: 225 | P44: 210 | R44: 37 | S44: 37 | T44: 26 | V44: Advanced | W44: 275 | X44: 37
...

Sheet Result
A2: OVERVIEW
C4: Data Type
C5: student_id | D5: Whole number
C6: course_level | D6: Text
C7: performance_score | D7: Whole number
C8: aptitude_score | D8: Whole number
C11: performance_score | F11: aptitude_score | J11: Performance
J12: Course Level | K12: Total | L12: Jumlah | M12: Rata Rata | N12: Max | O12: Min | P12: Standar Deviasi
C13: Mean | D13: 254.06667 | F13: Mean | G13: 44.24 | J13: Advanced | K13: 16195 | L13: 50 | M13: 323.9 | N13: 380 | O13: 250 | P13: 38.402939
C14: Standard Error | D14: 5.3303375 | F14: Standard Error | G14: 1.9782188 | J14: Foundation | K14: 9325 | L14: 50 | M14: 186.5 | N14: 245 | O14: 155 | P14: 17.67767
C15: Median | D15: 247.5 | F15: Median | G15: 38 | J15: Intermediate | K15: 12590 | L15: 50 | M15: 251.8 | N15: 355 | O15: 190 | P15: 39.145985
C16: Mode | D16: 355 | F16: Mode | G16: 21
C17: Standard Deviation | D17: 65.283035 | F17: Standard Deviation | G17: 24.228133 | J17: Aptitude
C18: Sample Variance | D18: 4261.8747 | F18: Sample Variance | G18: 587.00242 | J18: Course Level | K18: Total | L18: Jumlah | M18: Rata rata | N18: Max | O18: Min | P18: Standar Deviasi
C19: Kurtosis | D19: -1.1419921 | F19: Kurtosis | G19: -0.87170446 | J19: Advanced | K19: 3373 | L19: 50 | M19: 67.46 | N19: 97 | O19: 30 | P19: 19.171844
C20: Skewness | D20: 0.35309978 | F20: Skewness | G20: 0.58310354 | J20: Foundation | K20: 1126 | L20: 50 | M20: 22.52 | N20: 41 | O20: 9 | P20: 7.0283391
C21: Range | D21: 225 | F21: Range | G21: 88 | J21: Intermediate | K21: 2137 | L21: 50 | M21: 42.74 | N21: 90 | O21: 14 | P21: 18.279921
C22: Minimum | D22: 155 | F22: Minimum | G22: 9
C23: Maximum | D23: 380 | F23: Maximum | G23: 97 | J23: Performance | O23: Aptitude
C24: Sum | D24: 38110 | F24: Sum | G24: 6636 | J24: Percentile | K24: Advanced | L24: Intermediate | M24: Foundation | O24: Percentile | P24: Advanced | Q24: Intermediate | R24: Foundation
C25: Count | D25: 150 | F25: Count | G25: 150 | J25: Q1 | K25: =PERCENTILE(Bank!C2:C51,0.25) -> 295 | L25: =PERCENTILE(Bank!C52:C101,0.25) -> 225 | M25: =PERCENTILE(Bank!C102:C151,0.25) -> 175 | O25: Q1 | P25: =PERCENTILE(Bank!D2:D51,0.25) -> 50 | Q25: =PERCENTILE(Bank!D52:D101,0.25) -> 31 | R25: =PERCENTILE(Bank!D102:D151,0.25) -> 17.25
J26: Q2 (median) | K26: =PERCENTILE(Bank!C2:C51,0.5) -> 337.5 | L26: =PERCENTILE(Bank!C52:C101,0.5) -> 247.5 | M26: =PERCENTILE(Bank!C102:C151,0.5) -> 182.5 | O26: Q2 (median) | P26: =PERCENTILE(Bank!D2:D51,0.5) -> 70 | Q26: =PERCENTILE(Bank!D52:D101,0.5) -> 41.5 | R26: =PERCENTILE(Bank!D102:D151,0.5) -> 21
J27: Q3 | K27: =PERCENTILE(Bank!C2:C51,0.75) -> 355 | L27: =PERCENTILE(Bank!C52:C101,0.75) -> 278.75 | M27: =PERCENTILE(Bank!C102:C151,0.75) -> 195 | O27: Q3 | P27: =PERCENTILE(Bank!D2:D51,0.75) -> 83 | Q27: =PERCENTILE(Bank!D52:D101,0.75) -> 53.5 | R27: =PERCENTILE(Bank!D102:D151,0.75) -> 26
J28: IQR | K28: =K27-K25 -> 60 | L28: =L27-L25 -> 53.75 | M28: =M27-M25 -> 20 | O28: IQR | P28: =P27-P25 -> 33 | Q28: =Q27-Q25 -> 22.5 | R28: =R27-R25 -> 8.75
C31: 1. Do students with different performance levels enroll in different course levels?
C32: Anova: Single Factor
C34: SUMMARY | K34: Post Hoc
C35: Groups | D35: Count | E35: Sum | F35: Average | G35: Variance | K35: Level | L35: P value | M35: Significant
C36: Advanced | D36: 50 | E36: 16195 | F36: 323.9 | G36: 1474.7857 | K36: Advance VS Intermediate | L36: =TTEST(Bank!N2:N51,Bank!O2:O51,2,2) -> 4.0644336e-15 | M36: =IF(L36<=Result!$L$41,"Significant","Insignificant") -> Significant
C37: Intermediate | D37: 50 | E37: 12590 | F37: 251.8 | G37: 1532.4082 | K37: Intermediate VS Foundation | L37: =TTEST(Bank!O2:O51,Bank!P2:P51,2,2) -> 2.8720449e-18 | M37: =IF(L37<=Result!$L$41,"Significant","Insignificant") -> Significant
C38: Foundation | D38: 50 | E38: 9325 | F38: 186.5 | G38: 312.5 | K38: Foundation VS Advance | L38: =TTEST(Bank!N2:N51,Bank!P2:P51,2,2) -> 2.9822032e-41 | M38: =IF(L38<=Result!$L$41,"Significant","Insignificant") -> Significant
K40: P | L40: 0.005
C41: ANOVA | L41: =L40/3 -> 0.0016666667
C42: Source of Variation | D42: SS | E42: df | F42: MS | G42: F | H42: P-value | I42: F crit
C43: Between Groups | D43: 472354.33 | E43: 2 | F43: 236177.17 | G43: 213.43278 | H43: 3.3517914e-44 | I43: 3.0576207
C44: Within Groups | D44: 162665 | E44: 147 | F44: 1106.5646
C46: Total | D46: 635019.33 | E46: 149
C49: 2. Are there significant differences in aptitude scores across course levels?
C50: Anova: Single Factor
C52: SUMMARY | K52: Post Hoc
...
